Traceback (most recent call last):
  File "C:\Users\patwi\anaconda3\envs\jupyterbook\lib\site-packages\jupyter_cache\executors\utils.py", line 58, in single_nb_execution
    executenb(
  File "C:\Users\patwi\anaconda3\envs\jupyterbook\lib\site-packages\nbclient\client.py", line 1305, in execute
    return NotebookClient(nb=nb, resources=resources, km=km, **kwargs).execute()
  File "C:\Users\patwi\anaconda3\envs\jupyterbook\lib\site-packages\jupyter_core\utils\__init__.py", line 166, in wrapped
    return loop.run_until_complete(inner)
  File "C:\Users\patwi\anaconda3\envs\jupyterbook\lib\asyncio\base_events.py", line 647, in run_until_complete
    return future.result()
  File "C:\Users\patwi\anaconda3\envs\jupyterbook\lib\site-packages\nbclient\client.py", line 705, in async_execute
    await self.async_execute_cell(
  File "C:\Users\patwi\anaconda3\envs\jupyterbook\lib\site-packages\nbclient\client.py", line 1058, in async_execute_cell
    await self._check_raise_for_error(cell, cell_index, exec_reply)
  File "C:\Users\patwi\anaconda3\envs\jupyterbook\lib\site-packages\nbclient\client.py", line 914, in _check_raise_for_error
    raise CellExecutionError.from_cell_and_msg(cell, exec_reply_content)
nbclient.exceptions.CellExecutionError: An error occurred while executing the following cell:
------------------
import pandas as pd
import matplotlib.pyplot as plt
import numpy as np
import plotly.graph_objs as go
import plotly.express as px

# Loading datasets
df_tevredenheid = pd.read_csv('tevredenheid.csv', sep=";")
df_schuld = pd.read_csv('schuld.csv', sep=";")

# Replace spaces with underscores
df_tevredenheid.columns = df_tevredenheid.columns.str.replace(' ', '_')
df_schuld.columns = df_schuld.columns.str.replace(' ', '_')

# Replace '.' with NaN
df_tevredenheid.replace('.', np.nan, inplace=True)
df_schuld.replace('.', np.nan, inplace=True)

# Convert string to numeric
df_tevredenheid['ScoreGeluk_1'] = pd.to_numeric(df_tevredenheid['ScoreGeluk_1'], errors='coerce')
df_schuld['GemiddeldeHypotheekschuldEigenWoning_2'] = pd.to_numeric(df_schuld['GemiddeldeHypotheekschuldEigenWoning_2'], errors='coerce')
df_schuld['GemiddeldBesteedbaarInkomen_5'] = pd.to_numeric(df_schuld['GemiddeldBesteedbaarInkomen_5'], errors='coerce')
df_tevredenheid['ScoreTevredenheidFinancieleSituatie_9'] = pd.to_numeric(df_tevredenheid['ScoreTevredenheidFinancieleSituatie_9'], errors='coerce')
df_tevredenheid['ScoreZorgenOverFinancieleToekomst_13'] = pd.to_numeric(df_tevredenheid['ScoreZorgenOverFinancieleToekomst_13'], errors='coerce')

#Cleaning the Perioden column
df_tevredenheid['Perioden_clean'] = df_tevredenheid['Perioden'].str.replace('JJ00', '').astype(int)
df_schuld['Perioden_clean'] = df_schuld['Perioden'].str.replace('JJ00', '').astype(int)
------------------


[1;31m---------------------------------------------------------------------------[0m
[1;31mModuleNotFoundError[0m                       Traceback (most recent call last)
Cell [1;32mIn[1], line 1[0m
[1;32m----> 1[0m [38;5;28;01mimport[39;00m [38;5;21;01mpandas[39;00m [38;5;28;01mas[39;00m [38;5;21;01mpd[39;00m
[0;32m      2[0m [38;5;28;01mimport[39;00m [38;5;21;01mmatplotlib[39;00m[38;5;21;01m.[39;00m[38;5;21;01mpyplot[39;00m [38;5;28;01mas[39;00m [38;5;21;01mplt[39;00m
[0;32m      3[0m [38;5;28;01mimport[39;00m [38;5;21;01mnumpy[39;00m [38;5;28;01mas[39;00m [38;5;21;01mnp[39;00m

[1;31mModuleNotFoundError[0m: No module named 'pandas'

